terminate called after throwing an instance of 'std::domain_error'
  what():  udivide by zero
